Workbook
Name allowance: 'Charge-offs and Recoveries'!$C$27
Name CASHDIVCOM: 'Changes in Equity'!$B$12
Name CASHDIVPREF: 'Changes in Equity'!$B$11
Name RISKTOTASS: SUM('Calculation of Risk Weighted As'!$C$47:$F$47)
Name TOTASS: 'Bank Assets Analysis'!$H$39
Name TOTEQT: 'Changes in Equity'!$B$14
Name TOTLIAB: 'Bank Liabilities Analysis'!$H$35

Sheet Balance
A1: #FN1{101,100,223}
A2: БАЛАНСОВЫЙ ОТЧЕТ КОММЕРЧЕСКОГО БАНКА | C2: Таблица-1(Форма-0110BS)
A3: #FN1{10}
A4: #FNP{date_end}
A5: АКТИВЫ | B5: в тыс.сум
A7: 1. Кассовая наличность и другие платежные документы | C7: #FN1{101}
A8: 2. К получению из ЦБРУ | C8: -#FN1A{103,16103}
A9: 3. К получению из других банков | C9: #FN1{105}
A10: 4. Счета купли и продажи
A11: а. Ценные бумаги | B11: #FN1{10701-10795,10801-10895}
A12: б. Драгоценные металлы, монеты, камни | B12: #FN1{10901-10909}
A13: в. Минус: Резерв возможных убытков по счетам купли-продажи | B13: #FN1{10799,10899,10999}
A14: г. Счета купли-продажи, чистые | C14: =B11+B12-B13 -> #VALUE!
A15: 5 а. Инвестиции | B15: #FN1{15801-15821,15901-15993}
A16: б. Минус: Резерв возможных убытков по инвестициям | B16: #FN1{15899,15999}
A17: в. Инвестиции, чистые | C17: =B15-B16 -> #VALUE!
A18: 6. Ценные бумаги купленные по соглашению c обратным выкупом | C18: #FN1{118}
A19: 7. Ссуды и Лизинговые операции
A20: а. Брутто ссуды | B20: #FN1{1110,11195,1190,1210,1230,1240,1250,1260,1270,1290}+#FN1{1300,1310,1320,1330,1430,14501,14505,14701,14705,14801,14809,14901,14905}+#FN1{15001,15005,15101,15105,15201,15205,15301,15305,15401,15405}+#FN1{15501,15505,15701,15703}
A21: б. Лизинговые операции, Брутто | B21: #FN1{15601-15619,15705}
A22: в. Минус: Резерв возможных убытков по ссудам и лизингу | B22: #FN1{11199,12199,12399,12499,12599,12699,12799,12999}+#FN1{13099,13199,13299,13399,14399,14599,14799,14899,14999}+#FN1{15099,15199,15299,15399,15499,15599,15699,15799}
A23: г. Cсуды и лизинговые операции, чистые | C23: =B20+B21-B22 -> #VALUE!
A24: 8 а. Купленные векселя | B24: #FN1{11301-11395}
A25: б. Минус: Резерв возможных убытков по купленным векселям | B25: #FN1{11399}
A26: в. Купленные векселя, чистые | C26: =B24-B25 -> #VALUE!
A27: 9. Обязательства клиентов по финансовым инструментам | C27: #FN1{115,117}
A28: 10. Основные средства, чистые | C28: #FN1{165,166}
A29: 11. Начисленные проценты к получению | C29: #FN1{163}
A30: 12. Другое собственное имущество банка
A31: а. Инвестиции в недвижимость | B31: #FN1{16709}
A32: б. Другие активы, приобретенные при кредитных расчетах | B32: #FN1{16701,16703,16705,16713}
A33: в. Минус:Резервы на возможные убытки по другому собственному имуществу банка | B33: #FN1{16799}
A34: г. Чистые активы, приобретенные при ссудных расчетах | C34: =B31+B32-B33 -> #VALUE!
A35: 13. Другие активы | C35: =C36-C7-C8-C9-C14-C17-C18-C23-C26-C27-C28-C29-C34 -> #VALUE!
A36: 14. Итого активов | C36: =C78-C80 -> #VALUE!
A37: в том числе 16100 | C37: -#FN1A{161}
A38: ОБЯЗАТЕЛЬСТВА И АКЦИОНЕРНЫЙ КАПИТАЛ
A40: ОБЯЗАТЕЛЬСТВА
A41: 15. Депозиты до востребования | C41: #FN1{202,226}
A42: 16.Сберегательные депозиты | C42: #FN1{204,23604}
...

Sheet Income
B1: Приложение №1 к Рекомендациям по заполнению отчетности коммерческих банков по банковскому надзору представляемых Центральному банку Республики Узбекистан
A2: ОТЧЕТ О ПРИБЫЛЯХ И УБЫТКАХ | B2: Таблица-2 (Форма-0204IS)
A3: #FNP{date_end}
A4: Категории | B4: в тыс. сум
A5: 1. ПРОЦЕНТНЫЕ ДОХОДЫ
A6: a. Процентные доходы по счетам в ЦБРУ | B6: #FN1{402}
A7: б. Процентные доходы по счетам в других банках | B7: #FN1{404}
A8: в. Процентные доходы по купленным векселям | B8: #FN1{408}
A9: г. Процентные доходы по инвестициям | B9: #FN1{448}
A10: д. Процентные доходы по счетам купли-продажи ценных бумаг | B10: #FN1{406,407}
A11: е. Процентные доходы по обязательствам клиентов | B11: #FN1{410}
A12: ж. Процентные доходы по обяз-вам клиентов по непогашенным акцептам этого банка | B12: #FN1{412}
A13: з. Процент, Дисконт {Скидки} и взносы по ссудам и лизинговым операциям | B13: #FN1{414,416,418,419,420,421,422,423,424,425,426}+#FN1{436,437,439,440,441,442,443,444,445,446,447}+#FN1{451}
A14: и. Процентные доходы по соглашениям о покупке ценных бумаг с обратным выкупом | B14: #FN1{450}
A15: к. Другие процентные доходы | B15: #FN1{449}
A16: л. Итого процентных доходов | B16: =SUM(B6:B15) -> 0
A18: 2. ПРОЦЕНТНЫЕ РАСХОДЫ
A19: а. Процентные расходы по депозитам до востребования | B19: #FN1{501}
A20: б. Процентные расходы по сберегательным депозитам | B20: #FN1{506,54204}
A21: в. Процентные расходы по срочным депозитам | B21: #FN1{511,54206}
A22: г. Процентные расходы по счетам к оплате в ЦБРУ | B22: #FN1{516}
A23: д. Процентные расходы по счетам к оплате в другие банки | B23: #FN1{521}
A24: е. Итого процентных расходов по депозитам | B24: =SUM(B19:B23) -> 0
A25: ж. Процентные расходы по ссудам к оплате | B25: #FN1{531,541,54202,54208,54210}
A26: з. Процентные расходы по соглашениям о продаже ц/б с последующим выкупом | B26: #FN1{543}
A27: и. Другие процентные расходы | B27: #FN1{549,526}
A28: к. Итого процентных расходов по займам | B28: =SUM(B25:B27) -> 0
A29: л. Итого процентных расходов | B29: =B28+B24 -> 0
A31: 3. ЧИСТЫЕ ПРОЦЕНТНЫЕ ДОХОДЫ ДО ОЦЕНКИ ВОЗМОЖНЫХ УБЫТКОВ ПО ССУДАМ И ЛИЗИНГУ | B31: =B16-B29 -> 0
A32: а. Минус: Оценка возможных убытков по ссудам и лизингу | B32: #FN1{56802,56803,56814,56838,56842,56895}
A33: б. Чистые процентные доходы после оценки возможных убытков по ссудам и лизингу | B33: =B31-B32 -> #VALUE!
A35: 4. БЕСПРОЦЕНТНЫЕ ДОХОДЫ
A36: а. Доходы от комиссий и платы за услуги | B36: #FN1{452}
A37: б. Прибыль в иностранной валюте | B37: #FN1{454}
A38: в. Прибыль от коммерческих операций | B38: #FN1{456}
A39: г. Прибыль и дивиденды от инвестиций | B39: #FN1{457,458}
A40: д. Другие беспроцентные доходы | B40: #FN1{459}
A41: е. Итого беспроцентных доходов | B41: =SUM(B36:B40) -> 0
A43: 5. БЕСПРОЦЕНТНЫЕ РАСХОДЫ
A44: а. Комиссионные расходы и расходы за услуги | B44: #FN1{551}
...

Sheet Analysis of Interest
B1: Приложение №1 к Рекомендациям по заполнению отчетности коммерческих банков по банковскому надзору представляемых Центральному банку Республики Узбекистан
A2: АНАЛИЗ ПРОЦЕНТНЫХ ДОХОДОВ И РАСХОДОВ | B2: Таблица-3 (Форма-0206IS)
A3: #FNP{date_end}
A4: Категория | B4: в тыс. сум
A5: 1 . ПРОЦЕНТНЫЕ ДОХОДЫ ПО ССУДАМ И ЛИЗИНГОВЫМ ОПЕРАЦИЯМ
A6: a. Ссуды ЦБРУ и лизинговые операции | B6: #FN1{414}
A7: б. Ссуды другим банкам и лизинговые операции | B7: #FN1{416,440,45101}
A8: в. Ссуды Правительству и лизинговые операции | B8: #FN1{418,442}
A9: г. Ссуды физическим лицам и лизинговые операции | B9: #FN1{420,421,441,443,45103}
A10: д. Ссуды государственным предприятиям и лизинговые операции | B10: #FN1{422,444,45107}
A11: е. Ссуды совместным предприятиям и лизинговые операции | B11: #FN1{424,445,45109}
A12: ж. Ссуды частным товариществам и корпорациям и лизинговые операции | B12: #FN1{426,446,45105,45113}
A13: з. Другие ссуды и лизинговые операции | B13: #FN1{419,423,425,431,436,437,439,447,45111,45115,45117,45119,45121}
A14: и. ИТОГО ПРОЦЕНТНЫХ ДОХОДОВ ПО ССУДАМ | B14: =SUM(B6:B13) -> 0
A16: 2. ПРОЦЕНТНЫЕ ДОХОДЫ ПО КОР.СЧЕТАМ
A17: a. К получению из ЦБРУ | B17: #FN1{402}
A18: б. К получению из других банков | B18: #FN1{404}
A19: в. ИТОГО ПРОЦЕНТНЫХ ДОХОДОВ ПО КОР. СЧЕТАМ | B19: =SUM(B17:B18) -> 0
A21: 3. ПРОЦЕНТНЫЕ ДОХОДЫ ПО СЧЕТАМ КУПЛИ-ПРОДАЖИ Ц/Б
A22: a. Государственные казначейские ценные бумаги | B22: #FN1{40601,40605,40701,40705}
A23: б. Облигации и ценные бумаги ЦБРУ | B23: #FN1{40609,40709}
A24: в. Ценные бумаги государственных корпораций | B24: #FN1{40613,40713}
A25: г. Еврооблигации | B25: #FN1{40617,40717}
A26: д. Частные ценные бумаги
A27: е. Другие ценные бумаги | B27: #FN1{40694,40794}
A28: ж. ИТОГО ПРОЦЕНТНЫХ ДОХОДОВ ПО СЧЕТАМ КУПЛИ-ПРОДАЖИ Ц/Б | B28: =SUM(B22:B27) -> 0
A30: 4. ПРОЦЕНТНЫЕ ДОХОДЫ ПО ИНВЕСТИЦИЯМ
A31: а. Государственные облигации | B31: #FN1{44801,44805}
A32: б. Облигации и ценные бумаги ЦБРУ | B32: #FN1{44809}
A33: в. Частные облигации | B33: #FN1{44813}
A34: г. Еврооблигации | B34: #FN1{44817}
A35: д. Другие ценные бумаги | B35: #FN1{44894}
A36: е. ИТОГО ПРОЦЕНТНЫХ ДОХОДОВ ПО ИНВЕСТИЦИЯМ | B36: =SUM(B31:B35) -> 0
A38: 5. ДРУГИЕ ПРОЦЕНТНЫЕ ДОХОДЫ
A39: а. Процентные доходы по соглашениям о покупке ц/б c обратным выкупом | B39: #FN1{450}
A40: б. Другие процентные доходы | B40: #FN1{408,410,412,449}
A42: 6. ИТОГО ПРОЦЕНТНЫХ ДОХОДОВ | B42: =B14+B19+B28+B36+B39+B40 -> #VALUE!
A44: 7. ПРОЦЕНТНЫЕ РАСХОДЫ ПО ДЕПОЗИТАМ
A45: A. Депозиты до востребования
A46: а. Правительство | B46: #FN1{50101,50103,50104,50105,50107}
...

Sheet Bank Capital Calc.
D1: Приложение №1 к Рекомендациям по заполнению отчетности коммерческих банков по банковскому надзору представляемых Центральному банку Республики Узбекистан
A2: РАСЧЕТ КАПИТАЛА БАНКА | E2: Таблица-4 (Форма-3004CAR)
D4: #FNP{date_end}
A5: No. | B5: Характеристики | C5: Капитал
C6: Основной | D6: Дополнительный {Уровень 2} | E6: Итого капитала
B7: {A} | C7: {Б} | D7: {В} | E7: {Г}
A8: I. | B8: КАПИТАЛ УРОВНЯ 1 (до вычетов)
A9: 1 | B9: Обыкновенные Акции
A10: a | B10: Полностью оплаченные обыкновенные акции | C10: #FN1{30306,30312,30318}
A11: б | B11: Минус: Обратно Выкупленные акции | C11: #FN1{30324}
A12: в | B12: Выпущенные, полностью оплаченные обыкновенные акции | E12: =C10-C11 -> #VALUE!
A13: 2 | B13: Некумулятивные бессрочные привилегированные акции
A14: а | B14: Полностью оплаченные привилегированные акции | D14: #FN1{30303,30309,30315}
A15: б | B15: Минус: Обратно Выкупленные акции | D15: #FN1{30321}
A16: в | B16: Выпущенные, полностью оплаченные привилегированные акции | E16: =D14-D15 -> #VALUE!
A17: 3 | B17: Добавленный капитал | C17: #FN1{30603} | E17: =C17 -> #FN1{30603}
A18: 4 | B18: Нераспределенная прибыль
A19: а | B19: Капитальные резервы | C19: #FN1{30903,30904,30910}
A20: б | B20: Нераспределенная прибыль | C20: #FN1{31203}
A21: в | B21: Минус: Убыток за текущий год | C21: #FN1A{31206}
A22: г | B22: Итого нераспределенная прибыль | E22: =C19+C20+C21 -> #VALUE!
A23: 5 | B23: Интерес меньшинства в консолидированных дочерних компаниях {согласно МБС} | E23: =C23 -> 0
A24: 6 | B24: Доля участия дочерних предприятий (выпущенные дочерними предприятиями и находящиеся во владении третьих лиц инструменты, приравненные к капиталу) | E24: =D24 -> 0
A25: 7 | B25: Резерв на девальвацию | C25: #FN1{30906} | E25: =C25 -> #FN1{30906}
A26: 8 | B26: Итого капитал уровня 1 до вычетов | C26: =SUM(C10:C25) -> 0 | D26: =SUM(D10:D25) -> 0 | E26: =C26+D26 -> 0
A27: II | B27: ВЫЧЕТЫ ИЗ СУММЫ КАПИТАЛА УРОВНЯ I
A28: 1 | B28: Нематериальные активы | C28: #FN1{166} | E28: =-C28 -> #VALUE!
A29: 2 | B29: Все инвестиции в капитал неконсолидированных хозяйствующих субъектов, в том числе в долговые обязательства, которые образуют капитал хозяйствующих субъектов | C29: #FN1{10719, 10779, 10821, 10879,10711, 10813, 159} | E29: =-C29 -> #VALUE!
A30: 3 | B30: Инвестиции в капитал других банков | C30: #FN1{158} | E30: =-C30 -> #VALUE!
A31: 4 | B31: Итого вычетов из суммы капитала Уровня 1 | C31: =SUM(C28:C30) -> 0 | E31: =SUM(E28:E30) -> #VALUE!
A32: III | B32: СКОРРЕКТИРОВАННЫЙ КАПИТАЛ УРОВНЯ I | E32: =E12+E16+E17+E22+E23+E24+E25+E31 -> #VALUE!
A34: IV | B34: КАПИТАЛ УРОВНЯ II
A36: 1 | B36: Прибыль за текущий год (при подтверждении аудиторами - 100%, в противном случае 50% от суммы) | C36: #FN1A{4,5,31206,30907,30909} | E36: =C36 -> #FN1A{4,5,31206,30907,30909}
A37: 2 | B37: Резервы, создаваемые на стандартные кредиты (активы), в размере не более 1.25% от общей суммы активов, взвешенных с учетом риска | C37: ='Loan Classification'!G16 -> 0 | E37: =C37 -> 0
A38: 3 | B38: Субординированный долг | E38: =C38 -> 0
A39: 4 | B39: Излишки оценочной стоимости прироста над первоначальной стоимостью | C39: =F39*D39 -> #VALUE! | D39: 0.45 | E39: =C39 -> #VALUE! | F39: #FN1{30908}
A40: 5 | B40: Другие инструменты капитала, в том числе обязательства смешанного типа (не более 1/3 части капитала 1 уровня после вычетов) | E40: =C40 -> 0
A41: 6 | B41: Вычеты превышения Капитала Уровня II над Капиталом Уровня I | E41: 0
A42: 7 | B42: Итого капитала Уровня II | C42: =SUM(C36:C41) -> #VALUE! | E42: =SUM(E36:E40) -> #VALUE!
A43: V | B43: СКОРРЕКТИРОВАННЫЙ КАПИТАЛ УРОВНЯ II | E43: =E42-E41 -> #VALUE!
...

Sheet Calculation of Risk Weighted As
E1: Приложение №1 к Рекомендациям по заполнению отчетности коммерческих банков по банковскому надзору представляемых Центральному банку Республики Узбекистан
A2: РАСЧЕТ АКТИВОВ ВЗВЕШЕННЫХ С УЧЕТОМ РИСКА | F2: Таблица-5 (Форма-3006CAR)
A3: #FNP{date_end} | D3: 0
A5: # | B5: Характеристики | C5: 0 | D5: 0.2 | E5: 0.5 | F5: 1 | G5: 1.5 | I5: #FN1{119} | J5: FN1{119}
C6: Риск | D6: Риск | E6: Риск | F6: Риск | G6: Риск | I6: #FN1{121} | J6: FN1{121}
B7: (A) | C7: (Б) | D7: (В) | E7: (Г) | F7: (Д) | G7: (Е) | I7: #FN1{123} | J7: FN1{123}
B8: Балансовые Активы | I8: #FN1{145} | J8: FN1{145}
A9: 1. | B9: Касса (наличность и монеты) и Драгоценные металлы | C9: #FN1{10101-10107,10111,10198,109} | I9: #FN1{147} | J9: FN1{147}
A10: 2 | B10: Денежная наличность и другие платежные документы в пути | D10: #FN1{10109}
A11: 3 | B11: Корреспондентские и резервные счета в ЦБРУ | C11: #FN1{103,16103}
A12: 4 | B12: Корр. счета, кредиты и другие требования к другим банкам и депозитарным институтам | C12: #FN1{105,121,145}
A13: а | B13: требования к банкам стран с низким уровнем риска
A14: б | B14: требования к другим банкам | F14: =C12-D13 -> #VALUE!
A15: 5 | B15: Рыночные ценные бумаги, чистые | C15: #FN1{10701,10705,10709,10801,10805,10809}
A16: а. | B16: Ценные бумаги, выпущенные Правительством Республики Узбекистан и ЦБРУ | C16: =C15-C17 -> #VALUE!
A17: б | B17: Ценные бумаги, выпущенные правительствами и центральными банками стран, с низким уровня риска, а также другие требования к центральным банкам и правительствам этих стран
A18: в | B18: Другие ценные бумаги | F18: #FN1{10711,10715,10719,10779,10795}+#FN1{10813,10817,10821,10879,10889,10895}+#FN1{113,115,117,118}
A19: 6 | B19: Кредиты и другие активы или их части, обеспеченные наличными деньгами, хранящимися на отдельном блокированном депозитном счете. | C19: =I19+H19 -> #VALUE! | H19: #FNOBES{111,123,124,125,126,127,129,130,131,132,133;;;25;;E} | I19: #FNOBES{143,147,148,149,150,151,152,153,154,155,156,157;;;25;;E}
A20: 7 | B20: Все требования банка, деноминированные в местную валюту стран не входящих в группу стран с низким уровнем риска, к Центральным банкам и центральным правительствам этих стран
A21: 8 | B21: Активы, обеспеченные ценными бумагами выпущенными банками зарегистрированными в странах с низким уровнем риска
A22: 9. | B22: Требования банка к международным кредитным организациям, а также активы, гарантированные этими организациями
A23: 10. | B23: Активы или их части, обеспеченные залогом в виде ценных бумаг, оцененных по текущей рыночной стоимости и эмитированных международными финансовыми институтами
A24: 11. | B24: Кредиты и лизинг, чистые | C24: #FN1{11101,11195,11199,12301,12309,12399,12401,12409,12499,12501,12509,12599,12601,12609,12699,12701,12709,12799,12901,12909,12999,13001,13009,13099,13101,13109,13199,13201,13209,13299,13301,13309,13399}+#FN1{143,147,149,150,151,152,153,154,155}
A25: а) | B25: Прямые требования к Правительству и Центральному банку Республики Узбекистан | C25: #FN1{119,123,147}
A26: б) | B26: Активы или их части, обеспеченные ценными бумагами, которые оцененные по текущей рыночной стоимости и выпущенными или гарантированными Правительством Республики Узбекистан, Центральным банком Республики Узбекистан или Правительствами стран с низким уровнем риска. | D26: =H26+I26+J26+K26 -> #VALUE! | H26: #FNOBES{111,123,124,125,126,127,129,130,131,132,133;;;31;;E} | I26: #FNOBES{143,147,148,149,150,151,152,153,154,155,156,157;;;31;;E} | J26: #FNOBES{111,123,124,125,126,127,129,130,131,132,133;;;42;;E} | K26: #FNOBES{143,147,148,149,150,151,152,153,154,155,156,157;;;42;;E}
A27: в) | B27: Кредиты на недвижимость обеспеченные приобретаемым или строящимся домом (квартирой) | E27: =H27+I27+J27+K27 -> #VALUE! | H27: #FNOBES{111,123,124,125,126,127,129,130,131,132,133;;;21;;E} | I27: #FNOBES{143,147,148,149,150,151,152,153,154,155,156,157;;;21;;E} | J27: #FNOBES{111,123,124,125,126,127,129,130,131,132,133;;;22;;E} | K27: #FNOBES{143,147,148,149,150,151,152,153,154,155,156,157;;;22;;E}
A28: г) | B28: Реструктуризированные кредиты и кредиты в статусе "ненаращивания"
A29: д) | B29: Кредиты, по которым банк не имеет приоритетного права на залог
A30: е) | B30: Пересмотренные или пролонгированные кредиты и лизинги более одного раза | G30: #FN1{12109,12309,12409,12509,12609,12709,12909,13009,13109,13209,13309,15619}+#FN1{14705,14905,15005,15105,15205,15305,15405,15505}
A31: ж) | B31: все другие кредиты (кроме лизинга) | F31: =C24-C25-D26-E27-F28-F29 -> #VALUE!
A32: 12. | B32: Кредиты и лизинг в судебном разбирательстве | G32: #FN1{11105,157}
A33: 13. | B33: Просроченные кредиты и лизинг чистый | G33: #FN1{11103,12105,12305,12405,12505,12605,12705,12905,13005,13105,13205,13305,15617}
A34: 14 | B34: Финансовый лизинг | F34: #FN1{156}
A35: 15 | B35: Основные средства
A36: а) | B36: Основные средства, используемые в банковской деятельности (минус амортизация) | F36: #FN1{165}
A37: б) | B37: Недвижимое имущество принятое на баланс банка в целях полного или частичного погащения задолженности | G37: #FN1{16701, 16703}
A38: в) | B38: Недвижимое имущество банка, которым банк не пользуется более двух лет | G38: #FN1{16705, 16709}
A39: 16 | B39: Инвестиции в капитал неконсолидированных банковских и небанковских финансовых дочерних компаний и всех нефинансовых предприятий | C39: #FN1{158,159}
A40: 17 | B40: Все другие инвестиции, чистые | F40: 0
A41: 18 | B41: Нематериальные активы, включая гудвилл | C41: #FN1{166}
...

Sheet Calculation of Risk
C1: Приложение №1 к Рекомендациям по заполнению отчетности коммерческих банков по банковскому надзору представляемых Центральному банку Республики Узбекистан
A2: РАСЧЕТ ПО ОПЕРАЦИОННЫМ И РЫНОЧНЫМ РИСКАМ
C3: Таблица-5А (Форма-3006CAR)
B4: #FNP{date_end}
A5: № | B5: Наименование показателя | C5: в тыс. сум
A6: 1. | B6: Валовый доход банка за 2012 год | C6: =SUM(C7:C9) -> 0
A7: а. | B7: процентные доходы
A8: б. | B8: процентные расходы
A9: в. | B9: другие доходы
A10: 2. | B10: Валовый доход банка за 2013 год | C10: =SUM(C11:C13) -> 0
A11: а. | B11: процентные доходы
A12: б. | B12: процентные расходы
A13: в. | B13: другие доходы
A14: 3. | B14: Валовый доход банка за 2014 год | C14: =SUM(C15:C17) -> 0
A15: а. | B15: процентные доходы
A16: б. | B16: процентные расходы
A17: в. | B17: другие доходы
A18: 4. | B18: Средний валовый доход банка (за последние три года) | C18: =(C6+C10+C14)/3 -> 0
A19: 5. | B19: Сумма операционных рисков | C19: =100/C26*C18*0.15 -> 0
A21: 6. | B21: Счета валютной позиции (счет 17101 (сумовая часть)) | C21: #FN13{17101;000}/1000
A22: 7. | B22: Продажа на условиях Своп и Форвард (счет 92709, 92732) | C22: #FN1{92709,92732}
A23: 8. | B23: Покупка на условиях Своп и Форвард (счет 92716, 92736) | C23: #FN1{92716,92736}
A24: 9. | B24: Открытая валютная позиция, всего | C24: =C21+(C22-C23) -> #VALUE!
A25: 10. | B25: Сумма рыночных рисков | C25: =100/C26*C24*0.1 -> #VALUE!
A26: 11. | B26: Действуюший минимальное требование к достаточности капитала | C26: 11.5
A28: Подпись Председателя правления:
A30: Подпись Главного Бухгалтера:

Sheet Changes in Equity
B1: Приложение №1 к Рекомендациям по заполнению отчетности коммерческих банков по банковскому надзору представляемых Центральному банку Республики Узбекистан
A2: ИЗМЕНЕНИЯ В АКЦИОНЕРНОМ КАПИТАЛЕ | B2: Таблица-6 (Форма-3106CSA)
A3: #FNP{date_end} | C3: #FN1D{303;B} | D3: #FN1D{303;E} | E3: =D3-C3 -> #VALUE! | F3: 303
A4: Категория | B4: в тыс. сум | C4: #FN1D{306;B} | D4: #FN1D{306;E} | E4: =D4-C4 -> #VALUE! | F4: 306
A5: 1. Итого собственного капитала первоначально определенного за прошлый год | B5: #FN1D{303,306,309,312;B} | C5: #FN1D{309;B} | D5: #FN1D{309;E} | E5: =D5-C5 -> #VALUE! | F5: 309
A6: 2. Исправления в собственном капитале не показанные в отчете за прошлый год, чистые | C6: #FN1D{312;B} | D6: #FN1D{312;E} | E6: =D6-C6 -> #VALUE! | F6: 312 | I6: fn1 303
A7: 3. Исправленный баланс на конец прошлого календарного года (сумма строк 1 и 2) | B7: =SUM(B5:B6) -> 0 | C7: =SUM(C3:C6) -> 0 | D7: =SUM(D3:D6) -> 0 | E7: =D7-C7 -> 0 | I7: 30300 | J7: 10101-b | K7: 10101-e
A8: 4. Чистый прибыль (убыток) по состоянию на дату от начала года | B8: #FN1{4,5}
A9: 5. Продажа, Обмен, Приобретение или выкуп акций, за текущий год (чистая выручка) | B9: =D9-C9 -> #VALUE! | C9: #FN1D{303,306;B} | D9: #FN1D{303,306;E} | E9: =D9-C9 -> #VALUE! | F9: 303.306 | I9: #FN1{30303} | J9: #FN1D{10101;B} | K9: #FN1D{10101E}
A10: 6. Изменения в оценочной стоимости прироста над первонач. стоимостью, за текущий год (чистые) | B10: =D10-C10 -> #VALUE! | C10: #FN1D{30908;B} | D10: #FN1D{30908;E} | E10: =D10-C10 -> #VALUE! | F10: 30908 | I10: #FN1{30306}
A11: 7. МИНУС: Денежные дивиденды объявленные по привилегированным акциям | I11: #FN1{30309}
A12: 8. МИНУС: Денежные дивиденды объявленные по обыкновенным акциям | I12: #FN1{30312}
A13: 9. Другие статьи влияющие на собственный капитал за текущий год (чистые) | I13: #FN1{30315}
A14: 10. Итого собственного капитала на конец текущего периода (сумма строк с 3 по 10) | B14: #FN1{303,306,309,312,4,5} | I14: #FN1{30318}
I15: #FN1{30331}
A16: Подпись Руководителя: | I16: #FN1{30324}
A17: Подпись Главного Бухгалтера: | I17: =I9+I10+I11+I12+I13+I14+I15+I16 -> #VALUE!
C22: ручной ввод

Sheet Recociliation
B1: Приложение №1 к Рекомендациям по заполнению отчетности коммерческих банков по банковскому надзору представляемых Центральному банку Республики Узбекистан
A2: ВЫВЕРКА НЕРАСПРЕДЕЛЕННОЙ ПРИБЫЛИ | B2: Таблица-7 (Форма-0208IS)
A3: #FNP{date_end} | B3: в тыс. сум
A4: 1. Нераспределенная прибыль, указанная в отчете за предыдущий календарный год | B4: #FN1D{30903,30904,30907,312,30905,30909;B}
A5: 2. Плюс или Минус: Предварит. корректировки не указанные в отчете к концу года
A6: 3. Равно: Откорректированная нераспределенная прибыль | B6: =SUM(B4:B5) -> 0
A7: 4. Плюс или Минус: Кумулятивная чистая прибыль (Убытки) в текущем году | B7: #FN1{4,5}
A8: 5. Минус: Денежные дивиденды объявленные по обыкновенным акциям
A9: 6. Минус: Денежные дивиденды объявленные по привилегированным акциям
A10: 7. Минус: Дивиденды в виде акций объявленные по обыкновенным акциям
A11: 8. Минус: Дивиденды в виде акций объявленные по привилегированным акциям
A12: 9. Другие статьи, влияющие на нераспределенную прибыль,Чистые | B12: =B13-B6-B7+B8+B9+B10+B11 -> #VALUE!
A13: 10. Равно: Текущий Баланс, Нераспределенная прибыль | B13: #FN1{4,5,30903,30904,30907,312,30905,30909}
A15: Подпись Руководителя:
A16: Подпись Главного Бухгалтера:
C17: ручной ввод

Sheet Loans Receivable
R1: Приложение №1 к Рекомендациям по заполнению отчетности коммерческих банков по банковскому надзору представляемых Центральному банку Республики Узбекистан
A2: Кредиты к получению по отраслям экономики, типам клиентов и по типу обеспечения | R2: Таблица-8 (Форма-1516LES)
B3: #FNP{date_end} | X3: Контроль
C5: сумма В и Г | D5: срочные+рестр | G5: просрочка + в суде | K5: из них | AU5: просрочка + в суде
B6: Отрасль экономики | C6: Сумма кредитов | D6: Начисляемые кредиты | E6: 15701 на основном ссудном счете | F6: Просрочка | G6: Неначисляемые кредиты | H6: Средняя процентная ставка | I6: Депозиты | J6: Гарантированные Правительством Республики Узбекистан | K6: Гарантированные Правительством Р Уз. в ин. валюте | L6: Транспортные средства | M6: Инвентарь | N6: Недвижимость | O6: Оборудование | P6: Векселя {облигации,31,32,33,34,35,36,37} | Q6: Акции | R6: Гарантия третьей стороны | S6: Поручительства третьей стороны | T6: Страховой полис | U6: Необеспеченные | V6: Другое обеспечение | AU6: Неначисляемые кредиты
A7: Код | B7: (А) | C7: (Б) | D7: (В) | G7: (Г) | H7: (Д) | I7: (Е) | J7: (Ж) | K7: (Ж1) | L7: (З) | M7: (И) | N7: (К) | O7: (Л) | P7: (М) | Q7: (Н) | R7: (О) | S7: (П) | T7: (Р) | U7: (С) | V7: (Т)
B8: Промышленность
A9: =A8+10 -> 10 | B9: Физические лица | C9: =D9+G9 -> #VALUE! | D9: #FNECTC{12501,12509,14901,14905,11101,13301,13309,14301,14305,15603;08;1;;E} | E9: #FNECTC{15701,15705;08;1;;E} | F9: #FNECTCP{12501,12509,14901,14905,11101,13301,13309,14301,14305,15603;08;1;;E} | G9: =E9+F9 -> #VALUE! | H9: #FN4{;12501-12509,14901,14905} | I9: #FNOBES{12501,12509,14901,14905,11101,13301,13309,14301,14305,15603;08;1;25;;E} | J9: #FNOBES{12501,12509,14901,14905,11101,13301,13309,14301,14305,15603;08;1;42;;E} | L9: #FNOBES{12501,12509,14901,14905,11101,13301,13309,14301,14305,15603;08;1;23;;E} | M9: #FNOBES{12501,12509,14901,14905,11101,13301,13309,14301,14305,15603;08;1;26;;E} | N9: #FNOBES{12501,12509,14901,14905,11101,13301,13309,14301,14305,15603;08;1;21,22;;E} | O9: #FNOBES{12501,12509,14901,14905,11101,13301,13309,14301,14305,15603;08;1;24;;E} | P9: #FNOBES{12501,12509,14901,14905,11101,13301,13309,14301,14305,15603;08;1;31,32,33,34,35,36,37;;E} | Q9: #FNOBES{12501,12509,14901,14905,11101,13301,13309,14301,14305,15603;08;1;29;;E} | R9: #FNOBES{12501,12509,14901,14905,11101,13301,13309,14301,14305,15603;08;1;43;;E} | S9: #FNOBES{12501,12509,14901,14905,11101,13301,13309,14301,14305,15603;08;1;41;;E} | T9: #FNOBES{12501,12509,14901,14905,11101,13301,13309,14301,14305,15603;08;1;51;;E} | U9: #FNOBES{12501,12509,14901,14905,11101,13301,13309,14301,14305,15603;08;1;61;;E} | V9: =C9-I9-J9-L9-M9-N9-O9-P9-Q9-R9-S9-T9-U9 -> #VALUE! | X9: =SUM(I9:V9) -> #VALUE! | Y9: =C9-X9 -> #VALUE! | AU9: #FNECTCP{11103,11105,12505,13305,15617,15703,15705;08;1;;E}
A10: =A9+10 -> 20 | B10: Гос. предприятия | C10: =D10+G10 -> #VALUE! | D10: #FNECTC{12701,12709,15101,15105,11101,13301,13309,14301,14305,15607;02;1;;E} | E10: #FNECTC{15701,15705;02;1;;E} | F10: #FNECTCP{12701,12709,15101,15105,11101,13301,13309,14301,14305,15607;02;1;;E} | G10: =E10+F10 -> #VALUE! | H10: #FN4{1;12701-12709,15101,15105} | I10: #FNOBES{12701,12709,15101,15105,11101,13301,13309,14301,14305,15607;02;1;25;;E} | J10: #FNOBES{12701,12709,15101,15105,11101,13301,13309,14301,14305,15607;02;1;42;;E} | L10: #FNOBES{12701,12709,15101,15105,11101,13301,13309,14301,14305,15607;02;1;23;;E} | M10: #FNOBES{12701,12709,15101,15105,11101,13301,13309,14301,14305,15607;02;1;26;;E} | N10: #FNOBES{12701,12709,15101,15105,11101,13301,13309,14301,14305,15607;02;1;21,22;;E} | O10: #FNOBES{12701,12709,15101,15105,11101,13301,13309,14301,14305,15607;02;1;24;;E} | P10: #FNOBES{12701,12709,15101,15105,11101,13301,13309,14301,14305,15607;02;1;31,32,33,34,35,36,37;;E} | Q10: #FNOBES{12701,12709,15101,15105,11101,13301,13309,14301,14305,15607;02;1;29;;E} | R10: #FNOBES{12701,12709,15101,15105,11101,13301,13309,14301,14305,15607;02;1;43;;E} | S10: #FNOBES{12701,12709,15101,15105,11101,13301,13309,14301,14305,15607;02;1;41;;E} | T10: #FNOBES{12701,12709,15101,15105,11101,13301,13309,14301,14305,15607;02;1;51;;E} | U10: #FNOBES{12701,12709,15101,15105,11101,13301,13309,14301,14305,15607;02;1;61;;E} | V10: =C10-I10-J10-L10-M10-N10-O10-P10-Q10-R10-S10-T10-U10 -> #VALUE! | X10: =SUM(I10:V10) -> #VALUE! | Y10: =C10-X10 -> #VALUE! | AU10: #FNECTCP{11103,11105,12705,13305,15617,15701,15705;02;1;;E}
A11: 30 | B11: Совместные предприятия | C11: =D11+G11 -> #VALUE! | D11: #FNECTC{12901,12909,15301,15305,11101,13301,13309,14301,14305,15609;10;1;;E} | E11: #FNECTC{15701,15705;10;1;;E} | F11: #FNECTCP{12901,12909,15301,15305,11101,13301,13309,14301,14305,15609;10;1;;E} | G11: =E11+F11 -> #VALUE! | H11: #FN4{1;12901-12909,15301,15305} | I11: #FNOBES{12901,12909,15301,15305,11101,13301,13309,14301,14305,15609;10;1;25;;E} | J11: #FNOBES{12901,12909,15301,15305,11101,13301,13309,14301,14305,15609;10;1;42;;E} | L11: #FNOBES{12901,12909,15301,15305,11101,13301,13309,14301,14305,15609;10;1;23;;E} | M11: #FNOBES{12901,12909,15301,15305,11101,13301,13309,14301,14305,15609;10;1;26;;E} | N11: #FNOBES{12901,12909,15301,15305,11101,13301,13309,14301,14305,15609;10;1;21,22;;E} | O11: #FNOBES{12901,12909,15301,15305,11101,13301,13309,14301,14305,15609;10;1;24;;E} | P11: #FNOBES{12901,12909,15301,15305,11101,13301,13309,14301,14305,15609;10;1;31,32,33,34,35,36,37;;E} | Q11: #FNOBES{12901,12909,15301,15305,11101,13301,13309,14301,14305,15609;10;1;29;;E} | R11: #FNOBES{12901,12909,15301,15305,11101,13301,13309,14301,14305,15609;10;1;43;;E} | S11: #FNOBES{12901,12909,15301,15305,11101,13301,13309,14301,14305,15609;10;1;41;;E} | T11: #FNOBES{12901,12909,15301,15305,11101,13301,13309,14301,14305,15609;10;1;51;;E} | U11: #FNOBES{12901,12909,15301,15305,11101,13301,13309,14301,14305,15609;10;1;61;;E} | V11: =C11-I11-J11-L11-M11-N11-O11-P11-Q11-R11-S11-T11-U11 -> #VALUE! | X11: =SUM(I11:V11) -> #VALUE! | Y11: =C11-X11 -> #VALUE! | AU11: #FNECTCP{11103,11105,12905,13305,15617,15701,15705;10;1;;E}
A12: 40 | B12: Частные товарищества и корпорации | C12: =D12+G12 -> #VALUE! | D12: #FNECTC{13101,13109,15501,15505,11101,13301,13309,14301,14305,15613;09;1;;E} | E12: #FNECTC{15701,15705;09;1;;E} | F12: #FNECTCP{13101,13109,15501,15505,11101,13301,13309,14301,14305,15613;09;1;;E} | G12: =E12+F12 -> #VALUE! | H12: #FN4{1;13101-13109,15501-15505} | I12: #FNOBES{13101,13109,15501,15505,11101,13301,13309,14301,14305,15613;09;1;25;;E} | J12: #FNOBES{13101,13109,15501,15505,11101,13301,13309,14301,14305,15613;09;1;42;;E} | L12: #FNOBES{13101,13109,15501,15505,11101,13301,13309,14301,14305,15613;09;1;23;;E} | M12: #FNOBES{13101,13109,15501,15505,11101,13301,13309,14301,14305,15613;09;1;26;;E} | N12: #FNOBES{13101,13109,15501,15505,11101,13301,13309,14301,14305,15613;09;1;21,22;;E} | O12: #FNOBES{13101,13109,15501,15505,11101,13301,13309,14301,14305,15613;09;1;24;;E} | P12: #FNOBES{13101,13109,15501,15505,11101,13301,13309,14301,14305,15613;09;1;31,32,33,34,35,36,37;;E} | Q12: #FNOBES{13101,13109,15501,15505,11101,13301,13309,14301,14305,15613;09;1;29;;E} | R12: #FNOBES{13101,13109,15501,15505,11101,13301,13309,14301,14305,15613;09;1;43;;E} | S12: #FNOBES{13101,13109,15501,15505,11101,13301,13309,14301,14305,15613;09;1;41;;E} | T12: #FNOBES{13101,13109,15501,15505,11101,13301,13309,14301,14305,15613;09;1;51;;E} | U12: #FNOBES{13101,13109,15501,15505,11101,13301,13309,14301,14305,15613;09;1;61;;E} | V12: =C12-I12-J12-L12-M12-N12-O12-P12-Q12-R12-S12-T12-U12 -> #VALUE! | X12: =SUM(I12:V12) -> #VALUE! | Y12: =C12-X12 -> #VALUE! | AU12: #FNECTCP{11103,11105,13105,13305,15617,15701,15705;09;1;;E}
A13: 50 | B13: Правительство | C13: =D13+G13 -> #VALUE! | D13: #FNECTC{12301,12309,14701,14705,11101,13301,13309,14301,14305;01;1;;E} | E13: #FNECTC{15701,15705;01;1;;E} | F13: #FNECTCP{12301,12309,14701,14705,11101,13301,13309,14301,14305;01;1;;E} | G13: =E13+F13 -> #VALUE! | H13: #FN4{1;12301-12309,14701,14705} | I13: #FNOBES{12301,12309,14701,14705,11101,13301,13309,14301,14305;01;1;25;;E} | J13: #FNOBES{12301,12309,14701,14705,11101,13301,13309,14301,14305;01;1;42;;E} | L13: #FNOBES{12301,12309,14701,14705,11101,13301,13309,14301,14305;01;1;23;;E} | M13: #FNOBES{12301,12309,14701,14705,11101,13301,13309,14301,14305;01;1;26;;E} | N13: #FNOBES{12301,12309,14701,14705,11101,13301,13309,14301,14305;01;1;21,22;;E} | O13: #FNOBES{12301,12309,14701,14705,11101,13301,13309,14301,14305;01;1;24;;E} | P13: #FNOBES{12301,12309,14701,14705,11101,13301,13309,14301,14305;01;1;31,32,33,34,35,36,37;;E} | Q13: #FNOBES{12301,12309,14701,14705,11101,13301,13309,14301,14305;01;1;29;;E} | R13: #FNOBES{12301,12309,14701,14705,11101,13301,13309,14301,14305;01;1;43;;E} | S13: #FNOBES{12301,12309,14701,14705,11101,13301,13309,14301,14305;01;1;41;;E} | T13: #FNOBES{12301,12309,14701,14705,11101,13301,13309,14301,14305;01;1;51;;E} | U13: #FNOBES{12301,12309,14701,14705,11101,13301,13309,14301,14305;01;1;61;;E} | V13: =C13-I13-J13-L13-M13-N13-O13-P13-Q13-R13-S13-T13-U13 -> #VALUE! | X13: =SUM(I13:V13) -> #VALUE! | Y13: =C13-X13 -> #VALUE! | AU13: #FNECTCP{11103,11105,12305,13305,15617,15701,15705;01;1;;E}
B14: Бюджетные организации | C14: =D14+G14 -> #VALUE! | D14: #FNECTC{12401,12409,14801,14809,11101,13301,13309,14301,14305;12;1;;E} | E14: #FNECTC{15701,15705;12;1;;E} | F14: #FNECTCP{12401,12409,14801,14809,11101,13301,13309,14301,14305;12;1;;E} | G14: =E14+F14 -> #VALUE! | H14: #FN4{1;12401-12409,14801,14809} | I14: #FNOBES{12401,12409,14801,14809,11101,13301,13309,14301,14305;12;1;25;;E} | J14: #FNOBES{12401,12409,14801,14809,11101,13301,13309,14301,14305;12;1;42;;E} | L14: #FNOBES{12401,12409,14801,14809,11101,13301,13309,14301,14305;12;1;23;;E} | M14: #FNOBES{12401,12409,14801,14809,11101,13301,13309,14301,14305;12;1;26;;E} | N14: #FNOBES{12401,12409,14801,14809,11101,13301,13309,14301,14305;12;1;21,22;;E} | O14: #FNOBES{12401,12409,14801,14809,11101,13301,13309,14301,14305;12;1;24;;E} | P14: #FNOBES{12401,12409,14801,14809,11101,13301,13309,14301,14305;12;1;31,32,33,34,35,36,37;;E} | Q14: #FNOBES{12401,12409,14801,14809,11101,13301,13309,14301,14305;12;1;29;;E} | R14: #FNOBES{12401,12409,14801,14809,11101,13301,13309,14301,14305;12;1;43;;E} | S14: #FNOBES{12401,12409,14801,14809,11101,13301,13309,14301,14305;12;1;41;;E} | T14: #FNOBES{12401,12409,14801,14809,11101,13301,13309,14301,14305;12;1;51;;E} | U14: #FNOBES{12401,12409,14801,14809,11101,13301,13309,14301,14305;12;1;61;;E} | V14: =C14-I14-J14-L14-M14-N14-O14-P14-Q14-R14-S14-T14-U14 -> #VALUE! | X14: =SUM(I14:V14) -> #VALUE! | Y14: =C14-X14 -> #VALUE! | AU14: #FNECTCP{11103,11105,12405,13305,15617,15701,15705;12;1;;E}
B15: Предприниматели без обр. юр.лица | C15: =D15+G15 -> #VALUE! | D15: #FNECTC{12601,12609,15001,15005,11101,13301,13309,14301,14305,15605;11;1;;E} | E15: #FNECTC{15701,15705;11;1;;E} | F15: #FNECTCP{12601,12609,15001,15005,11101,13301,13309,14301,14305,15605;11;1;;E} | G15: =E15+F15 -> #VALUE! | H15: #FN4{1;12601-12609,15001,15005} | I15: #FNOBES{12601,12609,15001,15005,11101,13301,13309,14301,14305,15605;11;1;25;;E} | J15: #FNOBES{12601,12609,15001,15005,11101,13301,13309,14301,14305,15605;11;1;42;;E} | L15: #FNOBES{12601,12609,15001,15005,11101,13301,13309,14301,14305,15605;11;1;23;;E} | M15: #FNOBES{12601,12609,15001,15005,11101,13301,13309,14301,14305,15605;11;1;26;;E} | N15: #FNOBES{12601,12609,15001,15005,11101,13301,13309,14301,14305,15605;11;1;21,22;;E} | O15: #FNOBES{12601,12609,15001,15005,11101,13301,13309,14301,14305,15605;11;1;24;;E} | P15: #FNOBES{12601,12609,15001,15005,11101,13301,13309,14301,14305,15605;11;1;31,32,33,34,35,36,37;;E} | Q15: #FNOBES{12601,12609,15001,15005,11101,13301,13309,14301,14305,15605;11;1;29;;E} | R15: #FNOBES{12601,12609,15001,15005,11101,13301,13309,14301,14305,15605;11;1;43;;E} | S15: #FNOBES{12601,12609,15001,15005,11101,13301,13309,14301,14305,15605;11;1;41;;E} | T15: #FNOBES{12601,12609,15001,15005,11101,13301,13309,14301,14305,15605;11;1;51;;E} | U15: #FNOBES{12601,12609,15001,15005,11101,13301,13309,14301,14305,15605;11;1;61;;E} | V15: =C15-I15-J15-L15-M15-N15-O15-P15-Q15-R15-S15-T15-U15 -> #VALUE! | X15: =SUM(I15:V15) -> #VALUE! | Y15: =C15-X15 -> #VALUE! | AU15: #FNECTCP{11103,11105,12605,13305,15617,15701,15705;11;1;;E}
B16: Негосударственные, некомерческие организации | C16: =D16+G16 -> #VALUE! | D16: #FNECTC{13001,13009,15201,15205,11101,13301,13309,14301,14305,15611;03;1;;E} | E16: #FNECTC{15701,15705;03;1;;E} | F16: #FNECTCP{13001,13009,15201,15205,11101,13301,13309,14301,14305,15611;03;1;;E} | G16: =E16+F16 -> #VALUE! | H16: #FN4{1;13001-13009,15201-15205} | I16: #FNOBES{13001,13009,15201,15205,11101,13301,13309,14301,14305,15611;03;1;25;;E} | J16: #FNOBES{13001,13009,15201,15205,11101,13301,13309,14301,14305,15611;03;1;42;;E} | L16: #FNOBES{13001,13009,15201,15205,11101,13301,13309,14301,14305,15611;03;1;23;;E} | M16: #FNOBES{13001,13009,15201,15205,11101,13301,13309,14301,14305,15611;03;1;26;;E} | N16: #FNOBES{13001,13009,15201,15205,11101,13301,13309,14301,14305,15611;03;1;21,22;;E} | O16: #FNOBES{13001,13009,15201,15205,11101,13301,13309,14301,14305,15611;03;1;24;;E} | P16: #FNOBES{13001,13009,15201,15205,11101,13301,13309,14301,14305,15611;03;1;31,32,33,34,35,36,37;;E} | Q16: #FNOBES{13001,13009,15201,15205,11101,13301,13309,14301,14305,15611;03;1;29;;E} | R16: #FNOBES{13001,13009,15201,15205,11101,13301,13309,14301,14305,15611;03;1;43;;E} | S16: #FNOBES{13001,13009,15201,15205,11101,13301,13309,14301,14305,15611;03;1;41;;E} | T16: #FNOBES{13001,13009,15201,15205,11101,13301,13309,14301,14305,15611;03;1;51;;E} | U16: #FNOBES{13001,13009,15201,15205,11101,13301,13309,14301,14305,15611;03;1;61;;E} | V16: =C16-I16-J16-L16-M16-N16-O16-P16-Q16-R16-S16-T16-U16 -> #VALUE! | X16: =SUM(I16:V16) -> #VALUE! | Y16: =C16-X16 -> #VALUE! | AU16: #FNECTCP{11103,11105,13005,13305,15617,15701,15705;03;1;;E}
B17: Небанковские финансовые институты | C17: =D17+G17 -> #VALUE! | D17: #FNECTC{13201,13209,15401,15405,11101,13301,13309,14301,14305;04;1;;E} | E17: #FNECTC{15701,15705;04;1;;E} | F17: #FNECTCP{13201,13209,15401,15405,11101,13301,13309,14301,14305;04;1;;E} | G17: =E17+F17 -> #VALUE! | H17: #FN4{1;13201-13209,15401-15405} | I17: #FNOBES{13201,13209,15401,15405,11101,13301,13309,14301,14305;04;1;25;;E} | J17: #FNOBES{13201,13209,15401,15405,11101,13301,13309,14301,14305;04;1;42;;E} | L17: #FNOBES{13201,13209,15401,15405,11101,13301,13309,14301,14305;04;1;23;;E} | M17: #FNOBES{13201,13209,15401,15405,11101,13301,13309,14301,14305;04;1;26;;E} | N17: #FNOBES{13201,13209,15401,15405,11101,13301,13309,14301,14305;04;1;21,22;;E} | O17: #FNOBES{13201,13209,15401,15405,11101,13301,13309,14301,14305;04;1;24;;E} | P17: #FNOBES{13201,13209,15401,15405,11101,13301,13309,14301,14305;04;1;31,32,33,34,35,36,37;;E} | Q17: #FNOBES{13201,13209,15401,15405,11101,13301,13309,14301,14305;04;1;29;;E} | R17: #FNOBES{13201,13209,15401,15405,11101,13301,13309,14301,14305;04;1;43;;E} | S17: #FNOBES{13201,13209,15401,15405,11101,13301,13309,14301,14305;04;1;41;;E} | T17: #FNOBES{13201,13209,15401,15405,11101,13301,13309,14301,14305;04;1;51;;E} | U17: #FNOBES{13201,13209,15401,15405,11101,13301,13309,14301,14305;04;1;61;;E} | V17: =C17-I17-J17-L17-M17-N17-O17-P17-Q17-R17-S17-T17-U17 -> #VALUE! | X17: =SUM(I17:V17) -> #VALUE! | Y17: =C17-X17 -> #VALUE! | AU17: #FNECTCP{11103,11105,13205,13305,15617,15701,15705;04;1;;E}
A18: 60 | B18: Прочие | C18: =SUM(C14:C17) -> #VALUE! | D18: =SUM(D14:D17) -> 0 | E18: =SUM(E14:E17) -> 0 | F18: =SUM(F14:F17) -> 0 | G18: =SUM(G14:G17) -> #VALUE! | H18: =IF(C18=0,0,(H14*(C14/C18))+(H15*(C15/C18))+(H16*(C16/C18))+(H17*(C17/C18))) -> #VALUE! | I18: =SUM(I14:I17) -> 0 | J18: =SUM(J14:J17) -> 0 | L18: =SUM(L14:L17) -> 0 | M18: =SUM(M14:M17) -> 0 | N18: =SUM(N14:N17) -> 0 | O18: =SUM(O14:O17) -> 0 | P18: =SUM(P14:P17) -> 0 | Q18: =SUM(Q14:Q17) -> 0 | R18: =SUM(R14:R17) -> 0 | S18: =SUM(S14:S17) -> 0 | ... U18: =SUM(U14:U17) -> 0 | V18: =C18-I18-J18-L18-M18-N18-O18-P18-Q18-R18-S18-T18-U18 -> #VALUE! | X18: =SUM(I18:V18) -> #VALUE! | Y18: =C18-X18 -> #VALUE!
A19: 70 | B19: Итого по промышленности | C19: =SUM(C9:C13)+C18 -> #VALUE! | D19: =SUM(D9:D13)+D18 -> 0 | E19: =SUM(E9:E13)+E18 -> 0 | F19: =SUM(F9:F13)+F18 -> 0 | G19: =SUM(G9:G13)+G18 -> #VALUE! | H19: =IF(C19=0,"",(H9*(C9/C19))+(H10*(C10/C19))+(H11*(C11/C19))+(H12*(C12/C19))+(H13*(C13/C19))) -> #VALUE! | I19: =SUM(I9:I13)+I18 -> 0 | J19: =SUM(J9:J13)+J18 -> 0 | L19: =SUM(L9:L13)+L18 -> 0 | M19: =SUM(M9:M13)+M18 -> 0 | N19: =SUM(N9:N13)+N18 -> 0 | O19: =SUM(O9:O13)+O18 -> 0 | P19: =SUM(P9:P13)+P18 -> 0 | Q19: =SUM(Q9:Q13)+Q18 -> 0 | R19: =SUM(R9:R13)+R18 -> 0 | S19: =SUM(S9:S13)+S18 -> 0 | ... U19: =SUM(U9:U13)+U18 -> 0 | V19: =C19-I19-J19-L19-M19-N19-O19-P19-Q19-R19-S19-T19-U19 -> #VALUE! | X19: =SUM(I19:V19) -> #VALUE! | Y19: =C19-X19 -> #VALUE! | AU19: =SUM(AU9:AU17) -> 0
B20: Сельское хозяйство
A21: 80 | B21: Физические лица | C21: =D21+G21 -> #VALUE! | D21: =D162 -> #FNECTC{12501,12509,14901,14905,11101,13301,13309,14301,14305,15603;08;2;;E} | E21: =E162 -> #FNECTC{15701,15705;08;2;;E} | F21: =F162 -> #FNECTCP{12501,12509,14901,14905,11101,13301,13309,14301,14305,15603;08;2;;E} | G21: =G162 -> #VALUE! | H21: =H162 -> #FN4{;12501-12509,14901,14905} | I21: =I162 -> #FNOBES{12501,12509,14901,14905,11101,13301,13309,14301,14305,15603;08;2;25;;E} | J21: =J162 -> #FNOBES{12501,12509,14901,14905,11101,13301,13309,14301,14305,15603;08;2;42;;E} | L21: =L162 -> #FNOBES{12501,12509,14901,14905,11101,13301,13309,14301,14305,15603;08;2;23;;E} | M21: =M162 -> #FNOBES{12501,12509,14901,14905,11101,13301,13309,14301,14305,15603;08;2;26;;E} | N21: =N162 -> #FNOBES{12501,12509,14901,14905,11101,13301,13309,14301,14305,15603;08;2;21,22;;E} | O21: =O162 -> #FNOBES{12501,12509,14901,14905,11101,13301,13309,14301,14305,15603;08;2;24;;E} | P21: =P162 -> #FNOBES{12501,12509,14901,14905,11101,13301,13309,14301,14305,15603;08;2;31,32,33,34,35,36,37;;E} | Q21: =Q162 -> #FNOBES{12501,12509,14901,14905,11101,13301,13309,14301,14305,15603;08;2;29;;E} | R21: =R162 -> #FNOBES{12501,12509,14901,14905,11101,13301,13309,14301,14305,15603;08;2;43;;E} | S21: =S162 -> #FNOBES{12501,12509,14901,14905,11101,13301,13309,14301,14305,15603;08;2;41;;E} | ... U21: =U162 -> #FNOBES{12501,12509,14901,14905,11101,13301,13309,14301,14305,15603;08;2;61;;E} | V21: =C21-I21-J21-L21-M21-N21-O21-P21-Q21-R21-S21-T21-U21 -> #VALUE! | X21: =SUM(I21:V21) -> #VALUE! | Y21: =C21-X21 -> #VALUE! | AU21: #FNECTCP{11103,11105,12505,13305,15617,15703,15705;08;2;;E}
A22: 90 | B22: Гос. предприятия | C22: =D22+G22 -> #VALUE! | D22: =D165 -> #VALUE! | E22: =E165 -> #VALUE! | F22: =F165 -> #VALUE! | G22: =G165 -> #VALUE! | H22: =H165 -> #VALUE! | I22: =I165 -> #VALUE! | J22: =J165 -> #VALUE! | L22: =L165 -> #VALUE! | M22: =M165 -> #VALUE! | N22: =N165 -> #VALUE! | O22: =O165 -> #VALUE! | P22: =P165 -> #VALUE! | Q22: =Q165 -> #VALUE! | R22: =R165 -> #VALUE! | S22: =S165 -> #VALUE! | ... U22: =U165 -> #VALUE! | V22: =C22-I22-J22-L22-M22-N22-O22-P22-Q22-R22-S22-T22-U22 -> #VALUE! | X22: =SUM(I22:V22) -> #VALUE! | Y22: =C22-X22 -> #VALUE! | AU22: #FNECTCP{11103,11105,12705,13305,15617,15701,15705;02;2;;E}
A23: 100 | B23: Совместные предприятия | C23: =D23+G23 -> #VALUE! | D23: =D168 -> #VALUE! | E23: =E168 -> #VALUE! | F23: =F168 -> #VALUE! | G23: =G168 -> #VALUE! | H23: =H168 -> #VALUE! | I23: =I168 -> #VALUE! | J23: =J168 -> #VALUE! | L23: =L168 -> #VALUE! | M23: =M168 -> #VALUE! | N23: =N168 -> #VALUE! | O23: =O168 -> #VALUE! | P23: =P168 -> #VALUE! | Q23: =Q168 -> #VALUE! | R23: =R168 -> #VALUE! | S23: =S168 -> #VALUE! | ... U23: =U168 -> #VALUE! | V23: =C23-I23-J23-L23-M23-N23-O23-P23-Q23-R23-S23-T23-U23 -> #VALUE! | X23: =SUM(I23:V23) -> #VALUE! | Y23: =C23-X23 -> #VALUE! | AU23: #FNECTCP{11103,11105,12905,13305,15617,15701,15705;10;2;;E}
A24: 110 | B24: Частные товарищества и корпорации | C24: =D24+G24 -> #VALUE! | D24: =D171 -> #VALUE! | E24: =E171 -> #VALUE! | F24: =F171 -> #VALUE! | G24: =G171 -> #VALUE! | H24: =H171 -> #VALUE! | I24: =I171 -> #VALUE! | J24: =J171 -> #VALUE! | L24: =L171 -> #VALUE! | M24: =M171 -> #VALUE! | N24: =N171 -> #VALUE! | O24: =O171 -> #VALUE! | P24: =P171 -> #VALUE! | Q24: =Q171 -> #VALUE! | R24: =R171 -> #VALUE! | S24: =S171 -> #VALUE! | ... U24: =U171 -> #VALUE! | V24: =C24-I24-J24-L24-M24-N24-O24-P24-Q24-R24-S24-T24-U24 -> #VALUE! | X24: =SUM(I24:V24) -> #VALUE! | Y24: =C24-X24 -> #VALUE! | AU24: #FNECTCP{11103,11105,13105,13305,15617,15701,15705;09;2;;E}
A25: 120 | B25: Фермерское хозяйство | C25: =D25+G25 -> 0 | D25: =D158 -> 0 | E25: =E158 -> 0 | F25: =F158 -> 0 | G25: =G158 -> 0 | H25: =H158 -> 0 | I25: =I158 -> 0 | J25: =J158 -> 0 | L25: =L158 -> 0 | M25: =M158 -> 0 | N25: =N158 -> 0 | O25: =O158 -> 0 | P25: =P158 -> 0 | Q25: =Q158 -> 0 | R25: =R158 -> 0 | S25: =S158 -> 0 | ... U25: =U158 -> 0 | V25: =C25-I25-J25-L25-M25-N25-O25-P25-Q25-R25-S25-T25-U25 -> 0
A26: 130 | B26: Правительство | C26: =D26+G26 -> #VALUE! | D26: =D145 -> #VALUE! | E26: =E145 -> #VALUE! | F26: =F145 -> #VALUE! | G26: =G145 -> #VALUE! | H26: =H145 -> #VALUE! | I26: =I145 -> #VALUE! | J26: =J145 -> #VALUE! | L26: =L145 -> #VALUE! | M26: =M145 -> #VALUE! | N26: =N145 -> #VALUE! | O26: =O145 -> #VALUE! | P26: =P145 -> #VALUE! | Q26: =Q145 -> #VALUE! | R26: =R145 -> #VALUE! | S26: =S145 -> #VALUE! | ... U26: =U145 -> #VALUE! | V26: =C26-I26-J26-L26-M26-N26-O26-P26-Q26-R26-S26-T26-U26 -> #VALUE! | X26: =SUM(I26:V26) -> #VALUE! | Y26: =C26-X26 -> #VALUE! | AU26: #FNECTCP{11103,11105,12305,13305,15617,15701,15705;01;2;;E}
B27: Бюджетные организации | C27: =D27+G27 -> #VALUE! | D27: =D154 -> #VALUE! | E27: =E154 -> #VALUE! | F27: =F154 -> #VALUE! | G27: =G154 -> #VALUE! | H27: =H154 -> #VALUE! | I27: =I154 -> #VALUE! | J27: =J154 -> #VALUE! | L27: =L154 -> #VALUE! | M27: =M154 -> #VALUE! | N27: =N154 -> #VALUE! | O27: =O154 -> #VALUE! | P27: =P154 -> #VALUE! | Q27: =Q154 -> #VALUE! | R27: =R154 -> #VALUE! | S27: =S154 -> #VALUE! | ... U27: =U154 -> #VALUE! | V27: =C27-I27-J27-L27-M27-N27-O27-P27-Q27-R27-S27-T27-U27 -> #VALUE! | X27: =SUM(I27:V27) -> #VALUE! | Y27: =C27-X27 -> #VALUE! | AU27: #FNECTCP{11103,11105,12405,13305,15617,15701,15705;12;2;;E}
B28: Предприниматели без обр. юр.лица | C28: =D28+G28 -> #VALUE! | D28: =D190 -> #VALUE! | E28: =E190 -> #VALUE! | F28: =F190 -> #VALUE! | G28: =G190 -> #VALUE! | H28: =H190 -> #VALUE! | I28: =I190 -> #VALUE! | J28: =J190 -> #VALUE! | L28: =L190 -> #VALUE! | M28: =M190 -> #VALUE! | N28: =N190 -> #VALUE! | O28: =O190 -> #VALUE! | P28: =P190 -> #VALUE! | Q28: =Q190 -> #VALUE! | R28: =R190 -> #VALUE! | S28: =S190 -> #VALUE! | ... U28: =U190 -> #VALUE! | V28: =C28-I28-J28-L28-M28-N28-O28-P28-Q28-R28-S28-T28-U28 -> #VALUE! | X28: =SUM(I28:V28) -> #VALUE! | Y28: =C28-X28 -> #VALUE! | AU28: #FNECTCP{11103,11105,12605,13305,15617,15701,15705;11;2;;E}
B29: Негосударственные, некомерческие организации | C29: =D29+G29 -> #VALUE! | D29: =D184 -> #VALUE! | E29: =E184 -> #VALUE! | F29: =F184 -> #VALUE! | G29: =G184 -> #VALUE! | H29: =H184 -> #VALUE! | I29: =I184 -> #VALUE! | J29: =J184 -> #VALUE! | L29: =L184 -> #VALUE! | M29: =M184 -> #VALUE! | N29: =N184 -> #VALUE! | O29: =O184 -> #VALUE! | P29: =P184 -> #VALUE! | Q29: =Q184 -> #VALUE! | R29: =R184 -> #VALUE! | S29: =S184 -> #VALUE! | ... U29: =U184 -> #VALUE! | V29: =C29-I29-J29-L29-M29-N29-O29-P29-Q29-R29-S29-T29-U29 -> #VALUE! | X29: =SUM(I29:V29) -> #VALUE! | Y29: =C29-X29 -> #VALUE! | AU29: #FNECTCP{11103,11105,13005,13305,15617,15701,15705;03;2;;E}
B30: Небанковские финансовые институты | C30: =D30+G30 -> #VALUE! | D30: =D181 -> #VALUE! | E30: =E181 -> #VALUE! | F30: =F181 -> #VALUE! | G30: =G181 -> #VALUE! | H30: =H181 -> #VALUE! | I30: =I181 -> #VALUE! | J30: =J181 -> #VALUE! | L30: =L181 -> #VALUE! | M30: =M181 -> #VALUE! | N30: =N181 -> #VALUE! | O30: =O181 -> #VALUE! | P30: =P181 -> #VALUE! | Q30: =Q181 -> #VALUE! | R30: =R181 -> #VALUE! | S30: =S181 -> #VALUE! | ... U30: =U181 -> #VALUE! | V30: =C30-I30-J30-L30-M30-N30-O30-P30-Q30-R30-S30-T30-U30 -> #VALUE! | X30: =SUM(I30:V30) -> #VALUE! | Y30: =C30-X30 -> #VALUE! | AU30: #FNECTCP{11103,11105,13205,13305,15617,15701,15705;04;2;;E}
A31: 140 | B31: Прочие | C31: =SUM(C27:C30) -> #VALUE! | D31: =SUM(D27:D30) -> #VALUE! | E31: =SUM(E27:E30) -> #VALUE! | F31: =SUM(F27:F30) -> #VALUE! | G31: =SUM(G27:G30) -> #VALUE! | H31: =IF(C31=0,0,(H27*(C27/C31))+(H28*(C28/C31))+(H29*(C29/C31))+(H30*(C30/C31))) -> #VALUE! | I31: =SUM(I27:I30) -> #VALUE! | J31: =SUM(J27:J30) -> #VALUE! | L31: =SUM(L27:L30) -> #VALUE! | M31: =SUM(M27:M30) -> #VALUE! | N31: =SUM(N27:N30) -> #VALUE! | O31: =SUM(O27:O30) -> #VALUE! | P31: =SUM(P27:P30) -> #VALUE! | Q31: =SUM(Q27:Q30) -> #VALUE! | R31: =SUM(R27:R30) -> #VALUE! | S31: =SUM(S27:S30) -> #VALUE! | ... U31: =SUM(U27:U30) -> #VALUE! | V31: =C31-I31-J31-L31-M31-N31-O31-P31-Q31-R31-S31-T31-U31 -> #VALUE! | X31: =SUM(I31:V31) -> #VALUE! | Y31: =C31-X31 -> #VALUE!
A32: 150 | B32: Итого по сельскому хозяйству | C32: =SUM(C21:C26)+C31 -> #VALUE! | D32: =SUM(D21:D26)+D31 -> #VALUE! | E32: =SUM(E21:E26)+E31 -> #VALUE! | F32: =SUM(F21:F26)+F31 -> #VALUE! | G32: =SUM(G21:G26)+G31 -> #VALUE! | H32: =IF(C32=0,"",(H21*(C21/C32))+(H22*(C22/C32))+(H23*(C23/C32))+(H24*(C24/C32))+(H25*(C25/C32))+(H26*(C26/C32))) -> #VALUE! | I32: =SUM(I21:I26)+I31 -> #VALUE! | J32: =SUM(J21:J26)+J31 -> #VALUE! | L32: =SUM(L21:L26)+L31 -> #VALUE! | M32: =SUM(M21:M26)+M31 -> #VALUE! | N32: =SUM(N21:N26)+N31 -> #VALUE! | O32: =SUM(O21:O26)+O31 -> #VALUE! | P32: =SUM(P21:P26)+P31 -> #VALUE! | Q32: =SUM(Q21:Q26)+Q31 -> #VALUE! | R32: =SUM(R21:R26)+R31 -> #VALUE! | S32: =SUM(S21:S26)+S31 -> #VALUE! | ... U32: =SUM(U21:U26)+U31 -> #VALUE! | V32: =C32-I32-J32-L32-M32-N32-O32-P32-Q32-R32-S32-T32-U32 -> #VALUE! | X32: =SUM(I32:V32) -> #VALUE! | Y32: =C32-X32 -> #VALUE! | AU32: =SUM(AU27:AU30) -> 0
B33: Транспорт и коммуникации
A34: 160 | B34: Физические лица | C34: =D34+G34 -> #VALUE! | D34: #FNECTC{12501,12509,14901,14905,11101,13301,13309,14301,14305,15603;08;5;;E} | E34: #FNECTC{15701,15705;08;5;;E} | F34: #FNECTCP{12501,12509,14901,14905,11101,13301,13309,14301,14305,15603;08;5;;E} | G34: =E34+F34 -> #VALUE! | H34: #FN4{;12501-12509,14901,14905} | I34: #FNOBES{12501,12509,14901,14905,11101,13301,13309,14301,14305,15603;08;5;25;;E} | J34: #FNOBES{12501,12509,14901,14905,11101,13301,13309,14301,14305,15603;08;5;42;;E} | L34: #FNOBES{12501,12509,14901,14905,11101,13301,13309,14301,14305,15603;08;5;23;;E} | M34: #FNOBES{12501,12509,14901,14905,11101,13301,13309,14301,14305,15603;08;5;26;;E} | N34: #FNOBES{12501,12509,14901,14905,11101,13301,13309,14301,14305,15603;08;5;21,22;;E} | O34: #FNOBES{12501,12509,14901,14905,11101,13301,13309,14301,14305,15603;08;5;24;;E} | P34: #FNOBES{12501,12509,14901,14905,11101,13301,13309,14301,14305,15603;08;5;31,32,33,34,35,36,37;;E} | Q34: #FNOBES{12501,12509,14901,14905,11101,13301,13309,14301,14305,15603;08;5;29;;E} | R34: #FNOBES{12501,12509,14901,14905,11101,13301,13309,14301,14305,15603;08;5;43;;E} | S34: #FNOBES{12501,12509,14901,14905,11101,13301,13309,14301,14305,15603;08;5;41;;E} | T34: #FNOBES{12501,12509,14901,14905,11101,13301,13309,14301,14305,15603;08;5;51;;E} | U34: #FNOBES{12501,12509,14901,14905,11101,13301,13309,14301,14305,15603;08;5;61;;E} | V34: =C34-I34-J34-L34-M34-N34-O34-P34-Q34-R34-S34-T34-U34 -> #VALUE! | X34: =SUM(I34:V34) -> #VALUE! | Y34: =C34-X34 -> #VALUE! | AU34: #FNECTCP{11103,11105,12505,13305,15617,15703,15705;08;5;;E}
A35: 170 | B35: Гос. предприятия | C35: =D35+G35 -> #VALUE! | D35: #FNECTC{12701,12709,15101,15105,11101,13301,13309,14301,14305,15607;02;5;;E} | E35: #FNECTC{15701,15705;02;5;;E} | F35: #FNECTCP{12701,12709,15101,15105,11101,13301,13309,14301,14305,15607;02;5;;E} | G35: =E35+F35 -> #VALUE! | H35: #FN4{5;12701-12709,15101,15105} | I35: #FNOBES{12701,12709,15101,15105,11101,13301,13309,14301,14305,15607;02;5;25;;E} | J35: #FNOBES{12701,12709,15101,15105,11101,13301,13309,14301,14305,15607;02;5;42;;E} | L35: #FNOBES{12701,12709,15101,15105,11101,13301,13309,14301,14305,15607;02;5;23;;E} | M35: #FNOBES{12701,12709,15101,15105,11101,13301,13309,14301,14305,15607;02;5;26;;E} | N35: #FNOBES{12701,12709,15101,15105,11101,13301,13309,14301,14305,15607;02;5;21,22;;E} | O35: #FNOBES{12701,12709,15101,15105,11101,13301,13309,14301,14305,15607;02;5;24;;E} | P35: #FNOBES{12701,12709,15101,15105,11101,13301,13309,14301,14305,15607;02;5;31,32,33,34,35,36,37;;E} | Q35: #FNOBES{12701,12709,15101,15105,11101,13301,13309,14301,14305,15607;02;5;29;;E} | R35: #FNOBES{12701,12709,15101,15105,11101,13301,13309,14301,14305,15607;02;5;43;;E} | S35: #FNOBES{12701,12709,15101,15105,11101,13301,13309,14301,14305,15607;02;5;41;;E} | T35: #FNOBES{12701,12709,15101,15105,11101,13301,13309,14301,14305,15607;02;5;51;;E} | U35: #FNOBES{12701,12709,15101,15105,11101,13301,13309,14301,14305,15607;02;5;61;;E} | V35: =C35-I35-J35-L35-M35-N35-O35-P35-Q35-R35-S35-T35-U35 -> #VALUE! | X35: =SUM(I35:V35) -> #VALUE! | Y35: =C35-X35 -> #VALUE! | AU35: #FNECTCP{11103,11105,12705,13305,15617,15701,15705;02;5;;E}
A36: 180 | B36: Совместные предприятия | C36: =D36+G36 -> #VALUE! | D36: #FNECTC{12901,12909,15301,15305,11101,13301,13309,14301,14305,15609;10;5;;E} | E36: #FNECTC{15701,15705;10;5;;E} | F36: #FNECTCP{12901,12909,15301,15305,11101,13301,13309,14301,14305,15609;10;5;;E} | G36: =E36+F36 -> #VALUE! | H36: #FN4{5;12901-12909,15301,15305} | I36: #FNOBES{12901,12909,15301,15305,11101,13301,13309,14301,14305,15609;10;5;25;;E} | J36: #FNOBES{12901,12909,15301,15305,11101,13301,13309,14301,14305,15609;10;5;42;;E} | L36: #FNOBES{12901,12909,15301,15305,11101,13301,13309,14301,14305,15609;10;5;23;;E} | M36: #FNOBES{12901,12909,15301,15305,11101,13301,13309,14301,14305,15609;10;5;26;;E} | N36: #FNOBES{12901,12909,15301,15305,11101,13301,13309,14301,14305,15609;10;5;21,22;;E} | O36: #FNOBES{12901,12909,15301,15305,11101,13301,13309,14301,14305,15609;10;5;24;;E} | P36: #FNOBES{12901,12909,15301,15305,11101,13301,13309,14301,14305,15609;10;5;31,32,33,34,35,36,37;;E} | Q36: #FNOBES{12901,12909,15301,15305,11101,13301,13309,14301,14305,15609;10;5;29;;E} | R36: #FNOBES{12901,12909,15301,15305,11101,13301,13309,14301,14305,15609;10;5;43;;E} | S36: #FNOBES{12901,12909,15301,15305,11101,13301,13309,14301,14305,15609;10;5;41;;E} | T36: #FNOBES{12901,12909,15301,15305,11101,13301,13309,14301,14305,15609;10;5;51;;E} | U36: #FNOBES{12901,12909,15301,15305,11101,13301,13309,14301,14305,15609;10;5;61;;E} | V36: =C36-I36-J36-L36-M36-N36-O36-P36-Q36-R36-S36-T36-U36 -> #VALUE! | X36: =SUM(I36:V36) -> #VALUE! | Y36: =C36-X36 -> #VALUE! | AU36: #FNECTCP{11103,11105,12905,13305,15617,15701,15705;10;5;;E}
A37: 190 | B37: Частные товарищества и корпорации | C37: =D37+G37 -> #VALUE! | D37: #FNECTC{13101,13109,15501,15505,11101,13301,13309,14301,14305,15613;09;5;;E} | E37: #FNECTC{15701,15705;09;5;;E} | F37: #FNECTCP{13101,13109,15501,15505,11101,13301,13309,14301,14305,15613;09;5;;E} | G37: =E37+F37 -> #VALUE! | H37: #FN4{5;13101-13109,15501-15505} | I37: #FNOBES{13101,13109,15501,15505,11101,13301,13309,14301,14305,15613;09;5;25;;E} | J37: #FNOBES{13101,13109,15501,15505,11101,13301,13309,14301,14305,15613;09;5;42;;E} | L37: #FNOBES{13101,13109,15501,15505,11101,13301,13309,14301,14305,15613;09;5;23;;E} | M37: #FNOBES{13101,13109,15501,15505,11101,13301,13309,14301,14305,15613;09;5;26;;E} | N37: #FNOBES{13101,13109,15501,15505,11101,13301,13309,14301,14305,15613;09;5;21,22;;E} | O37: #FNOBES{13101,13109,15501,15505,11101,13301,13309,14301,14305,15613;09;5;24;;E} | P37: #FNOBES{13101,13109,15501,15505,11101,13301,13309,14301,14305,15613;09;5;31,32,33,34,35,36,37;;E} | Q37: #FNOBES{13101,13109,15501,15505,11101,13301,13309,14301,14305,15613;09;5;29;;E} | R37: #FNOBES{13101,13109,15501,15505,11101,13301,13309,14301,14305,15613;09;5;43;;E} | S37: #FNOBES{13101,13109,15501,15505,11101,13301,13309,14301,14305,15613;09;5;41;;E} | T37: #FNOBES{13101,13109,15501,15505,11101,13301,13309,14301,14305,15613;09;5;51;;E} | U37: #FNOBES{13101,13109,15501,15505,11101,13301,13309,14301,14305,15613;09;5;61;;E} | V37: =C37-I37-J37-L37-M37-N37-O37-P37-Q37-R37-S37-T37-U37 -> #VALUE! | X37: =SUM(I37:V37) -> #VALUE! | Y37: =C37-X37 -> #VALUE! | AU37: #FNECTCP{11103,11105,13105,13305,15617,15701,15705;09;5;;E}
A38: 200 | B38: Правительство | C38: =D38+G38 -> #VALUE! | D38: #FNECTC{12301,12309,14701,14705,11101,13301,13309,14301,14305;01;5;;E} | E38: #FNECTC{15701,15705;01;5;;E} | F38: #FNECTCP{12301,12309,14701,14705,11101,13301,13309,14301,14305;01;5;;E} | G38: =E38+F38 -> #VALUE! | H38: #FN4{5;12301-12309,14701,14705} | I38: #FNOBES{12301,12309,14701,14705,11101,13301,13309,14301,14305;01;5;25;;E} | J38: #FNOBES{12301,12309,14701,14705,11101,13301,13309,14301,14305;01;5;42;;E} | L38: #FNOBES{12301,12309,14701,14705,11101,13301,13309,14301,14305;01;5;23;;E} | M38: #FNOBES{12301,12309,14701,14705,11101,13301,13309,14301,14305;01;5;26;;E} | N38: #FNOBES{12301,12309,14701,14705,11101,13301,13309,14301,14305;01;5;21,22;;E} | O38: #FNOBES{12301,12309,14701,14705,11101,13301,13309,14301,14305;01;5;24;;E} | P38: #FNOBES{12301,12309,14701,14705,11101,13301,13309,14301,14305;01;5;31,32,33,34,35,36,37;;E} | Q38: #FNOBES{12301,12309,14701,14705,11101,13301,13309,14301,14305;01;5;29;;E} | R38: #FNOBES{12301,12309,14701,14705,11101,13301,13309,14301,14305;01;5;43;;E} | S38: #FNOBES{12301,12309,14701,14705,11101,13301,13309,14301,14305;01;5;41;;E} | T38: #FNOBES{12301,12309,14701,14705,11101,13301,13309,14301,14305;01;5;51;;E} | U38: #FNOBES{12301,12309,14701,14705,11101,13301,13309,14301,14305;01;5;61;;E} | V38: =C38-I38-J38-L38-M38-N38-O38-P38-Q38-R38-S38-T38-U38 -> #VALUE! | X38: =SUM(I38:V38) -> #VALUE! | Y38: =C38-X38 -> #VALUE! | AU38: #FNECTCP{11103,11105,12305,13305,15617,15701,15705;01;5;;E}
B39: Бюджетные организации | C39: =D39+G39 -> #VALUE! | D39: #FNECTC{12401,12409,14801,14809,11101,13301,13309,14301,14305;12;5;;E} | E39: #FNECTC{15701,15705;12;5;;E} | F39: #FNECTCP{12401,12409,14801,14809,11101,13301,13309,14301,14305;12;5;;E} | G39: =E39+F39 -> #VALUE! | H39: #FN4{5;12401-12409,14801,14809} | I39: #FNOBES{12401,12409,14801,14809,11101,13301,13309,14301,14305;12;5;25;;E} | J39: #FNOBES{12401,12409,14801,14809,11101,13301,13309,14301,14305;12;5;42;;E} | L39: #FNOBES{12401,12409,14801,14809,11101,13301,13309,14301,14305;12;5;23;;E} | M39: #FNOBES{12401,12409,14801,14809,11101,13301,13309,14301,14305;12;5;26;;E} | N39: #FNOBES{12401,12409,14801,14809,11101,13301,13309,14301,14305;12;5;21,22;;E} | O39: #FNOBES{12401,12409,14801,14809,11101,13301,13309,14301,14305;12;5;24;;E} | P39: #FNOBES{12401,12409,14801,14809,11101,13301,13309,14301,14305;12;5;31,32,33,34,35,36,37;;E} | Q39: #FNOBES{12401,12409,14801,14809,11101,13301,13309,14301,14305;12;5;29;;E} | R39: #FNOBES{12401,12409,14801,14809,11101,13301,13309,14301,14305;12;5;43;;E} | S39: #FNOBES{12401,12409,14801,14809,11101,13301,13309,14301,14305;12;5;41;;E} | T39: #FNOBES{12401,12409,14801,14809,11101,13301,13309,14301,14305;12;5;51;;E} | U39: #FNOBES{12401,12409,14801,14809,11101,13301,13309,14301,14305;12;5;61;;E} | V39: =C39-I39-J39-L39-M39-N39-O39-P39-Q39-R39-S39-T39-U39 -> #VALUE! | X39: =SUM(I39:V39) -> #VALUE! | Y39: =C39-X39 -> #VALUE! | AU39: #FNECTCP{11103,11105,12405,13305,15617,15701,15705;12;5;;E}
B40: Предприниматели без обр. юр.лица | C40: =D40+G40 -> #VALUE! | D40: #FNECTC{12601,12609,15001,15005,11101,13301,13309,14301,14305,15605;11;5;;E} | E40: #FNECTC{15701,15705;11;5;;E} | F40: #FNECTCP{12601,12609,15001,15005,11101,13301,13309,14301,14305,15605;11;5;;E} | G40: =E40+F40 -> #VALUE! | H40: #FN4{5;12601-12609,15001,15005} | I40: #FNOBES{12601,12609,15001,15005,11101,13301,13309,14301,14305,15605;11;5;25;;E} | J40: #FNOBES{12601,12609,15001,15005,11101,13301,13309,14301,14305,15605;11;5;42;;E} | L40: #FNOBES{12601,12609,15001,15005,11101,13301,13309,14301,14305,15605;11;5;23;;E} | M40: #FNOBES{12601,12609,15001,15005,11101,13301,13309,14301,14305,15605;11;5;26;;E} | N40: #FNOBES{12601,12609,15001,15005,11101,13301,13309,14301,14305,15605;11;5;21,22;;E} | O40: #FNOBES{12601,12609,15001,15005,11101,13301,13309,14301,14305,15605;11;5;24;;E} | P40: #FNOBES{12601,12609,15001,15005,11101,13301,13309,14301,14305,15605;11;5;31,32,33,34,35,36,37;;E} | Q40: #FNOBES{12601,12609,15001,15005,11101,13301,13309,14301,14305,15605;11;5;29;;E} | R40: #FNOBES{12601,12609,15001,15005,11101,13301,13309,14301,14305,15605;11;5;43;;E} | S40: #FNOBES{12601,12609,15001,15005,11101,13301,13309,14301,14305,15605;11;5;41;;E} | T40: #FNOBES{12601,12609,15001,15005,11101,13301,13309,14301,14305,15605;11;5;51;;E} | U40: #FNOBES{12601,12609,15001,15005,11101,13301,13309,14301,14305,15605;11;5;61;;E} | V40: =C40-I40-J40-L40-M40-N40-O40-P40-Q40-R40-S40-T40-U40 -> #VALUE! | X40: =SUM(I40:V40) -> #VALUE! | Y40: =C40-X40 -> #VALUE! | AU40: #FNECTCP{11103,11105,12605,13305,15617,15701,15705;11;5;;E}
